Workbook

Sheet README
B2: 10-YEAR COMPENSATION COMPARISON — CORRECTED MODEL
B4: Rebuilt from 10_year_Comp_Comparison_Calc.xlsx, tab "CompOffer Comparison".
B6: HOW TO USE
B7: 1. Scenarios tab: set the three growth scenarios. Every lever is editable.
B8: 2. Offer_1 / Offer_2 / Offer_3 / Current_Comp tabs: fill the blue input cells in rows 4-21.
B9: 3. Set the vesting schedules in rows 26-27. Each row must total 100% or the check cell reads ERROR.
B10: 4. Read results on the Comparison tab. Nothing on that tab is an input.
B12: COLOR LEGEND
B13: Blue text = hardcoded input, edit these.
B14: Black text = formula, do not edit.
B15: Green text = link to another tab.
B16: Yellow fill = key assumption.
... B50: The seeded example values in Offer_1 are the Google block from the original workbook.

Sheet Scenarios
A1: GROWTH SCENARIOS
A2: Blue cells are inputs. Every lever below is user-editable.
A3: Lever | C3: Conservative | D3: Medium | E3: Aggressive
A4: Share price appreciation %/yr | C4: 0 | D4: 0.07 | E4: 0.15 | G4: Medium 7%/yr is a long-run broad-market nominal assumption, NOT a forecast for any specific ticker.
A5: Merit increase factor (x offer input) | C5: 0.5 | D5: 1 | E5: 1.5 | G5: Aggressive 15%/yr is a placeholder. Replace with the ticker trailing 5-yr CAGR entered below, and cap it.
A6: Bonus performance multiplier | C6: 0.75 | D6: 1 | E6: 1.25 | G6: Applied to each offer tab merit % input. Conservative halves it; aggressive adds 50%.
A7: Refresher grant growth factor (x offer input) | C7: 0 | D7: 1 | E7: 1 | G7: Applied to bonus target %. Models below-target / at-target / above-target payout.
A8: Number of refresher grant years | C8: 4 | D8: 12 | E8: 12 | G8: Set to 0 in Conservative so refresher grant SIZE does not grow.
G9: Conservative assumes refreshers stop after 4 years. Medium/Aggressive run the full horizon.
A11: TICKER CONTEXT (manual entry — context only, not an input to the model)
A12: Trailing 1-year total return | G12: Past performance does not indicate future results. These cells feed nothing; they exist so the
A13: Trailing 5-year CAGR | G13: appreciation assumption above can be set with the trailing figures visible next to it.
A14: As-of date
A15: Suggested cap on aggressive appreciation | C15: 0.2
A17: Source of all values on this tab: user-entered assumptions. No market data is embedded in this workbook.

Sheet Offer_1
A1: OFFER 1
A2: Blue = you edit. Black = formula, do not edit. Green = link to another tab. Yellow = key assumption.
A3: INPUTS
A4: Company name | B4: Company A
A5: Ticker | B5: TICKA
A6: Start calendar year | B6: 2026
A7: Base salary at start | B7: 200000
A8: Merit increase %/yr | B8: 0.03
A9: Bonus target % of base | B9: 0.22
A10: Bonus basis (Current or Prior) | B10: Current
A11: Bonus paid in Year 1? (Yes/No) | B11: No
A12: Sign-on total | B12: 100000
A13: Sign-on % paid Year 1 | B13: 0.5
A14: Sign-on % paid Year 2 | B14: 0.5
A15: Sign-on % paid Year 3 | B15: 0
A16: Sign-on check (must equal 100%) | B16: =SUM(B13:B15) -> 1 | C16: =IF(ROUND(B16,6)=1,"OK","ERROR - must total 100%") -> OK
A17: Grant-date share price | B17: 150
A18: Initial grant value ($) | B18: 400000
A19: Refresher value, first grant ($) | B19: 150000
A20: First refresher calendar year | B20: 2027
A21: Refresher grant growth %/yr | B21: 0.03
A22: First vest timing (0 = grant year, 1 = year after) | B22: 1
A23: Share price is entered manually. Replace with a market data lookup in the web app. The original workbook vested in the grant year itself (offset 0); real grants usually vest a year later (offset 1).
A24: VESTING SCHEDULES — % of the grant that vests in each year AFTER the grant date
A25: Years after grant | C25: 1 | D25: 2 | E25: 3 | F25: 4 | G25: 5 | H25: 6 | I25: 7 | J25: 8 | K25: Total
A26: Initial grant | C26: 0.4 | D26: 0.28 | E26: 0.2 | F26: 0.12 | G26: 0 | H26: 0 | I26: 0 | J26: 0 | K26: =SUM(C26:J26) -> 1 | L26: =IF(ROUND(K26,6)=1,"OK","ERROR - must total 100%") -> OK
A27: Refresher grants | C27: 0.25 | D27: 0.25 | E27: 0.25 | F27: 0.25 | G27: 0 | H27: 0 | I27: 0 | J27: 0 | K27: =SUM(C27:J27) -> 1 | L27: =IF(ROUND(K27,6)=1,"OK","ERROR - must total 100%") -> OK
A28: Annual granularity. Sub-annual (quarterly/monthly) vesting and cliffs are handled in the web app, not here.
A31: SCENARIO: CONSERVATIVE | B31: =Scenarios!C$3 -> Conservative
A32: Year index | C32: 1 | D32: 2 | E32: 3 | F32: 4 | G32: 5 | H32: 6 | I32: 7 | J32: 8 | K32: 9 | L32: 10 | M32: 11 | N32: 12 | O32: 13 | P32: 14 | Q32: 15
A33: Calendar year | C33: =$B$6 -> 2026 | D33: =C33+1 -> 2027 | E33: =D33+1 -> 2028 | F33: =E33+1 -> 2029 | G33: =F33+1 -> 2030 | H33: =G33+1 -> 2031 | I33: =H33+1 -> 2032 | J33: =I33+1 -> 2033 | K33: =J33+1 -> 2034 | ... Q33: =P33+1 -> 2040
A34: Share price ($) | C34: =$B$17 -> 150 | D34: =C34*(1+Scenarios!$C$4) -> 150 | E34: =D34*(1+Scenarios!$C$4) -> 150 | F34: =E34*(1+Scenarios!$C$4) -> 150 | G34: =F34*(1+Scenarios!$C$4) -> 150 | H34: =G34*(1+Scenarios!$C$4) -> 150 | I34: =H34*(1+Scenarios!$C$4) -> 150 | J34: =I34*(1+Scenarios!$C$4) -> 150 | K34: =J34*(1+Scenarios!$C$4) -> 150 | ... Q34: =P34*(1+Scenarios!$C$4) -> 150
A35: Base salary | C35: =$B$7 -> 200000 | D35: =C35*(1+$B$8*Scenarios!$C$5) -> 203000 | E35: =D35*(1+$B$8*Scenarios!$C$5) -> 206045 | F35: =E35*(1+$B$8*Scenarios!$C$5) -> 209135.67 | G35: =F35*(1+$B$8*Scenarios!$C$5) -> 212272.71 | H35: =G35*(1+$B$8*Scenarios!$C$5) -> 215456.8 | I35: =H35*(1+$B$8*Scenarios!$C$5) -> 218688.65 | J35: =I35*(1+$B$8*Scenarios!$C$5) -> 221968.98 | K35: =J35*(1+$B$8*Scenarios!$C$5) -> 225298.52 | ... Q35: =P35*(1+$B$8*Scenarios!$C$5) -> 246351.15
A36: Bonus basis salary | C36: =IF($B$10="Prior",0,C35) -> 200000 | D36: =IF($B$10="Prior",C35,D35) -> 203000 | E36: =IF($B$10="Prior",D35,E35) -> 206045 | F36: =IF($B$10="Prior",E35,F35) -> 209135.67 | G36: =IF($B$10="Prior",F35,G35) -> 212272.71 | H36: =IF($B$10="Prior",G35,H35) -> 215456.8 | I36: =IF($B$10="Prior",H35,I35) -> 218688.65 | J36: =IF($B$10="Prior",I35,J35) -> 221968.98 | K36: =IF($B$10="Prior",J35,K35) -> 225298.52 | ... Q36: =IF($B$10="Prior",P35,Q35) -> 246351.15
A37: Annual bonus | C37: =IF($B$11="No",0,C36*$B$9*Scenarios!$C$6) -> 0 | D37: =D36*$B$9*Scenarios!$C$6 -> 33495 | E37: =E36*$B$9*Scenarios!$C$6 -> 33997.425 | F37: =F36*$B$9*Scenarios!$C$6 -> 34507.386 | G37: =G36*$B$9*Scenarios!$C$6 -> 35024.997 | H37: =H36*$B$9*Scenarios!$C$6 -> 35550.372 | I37: =I36*$B$9*Scenarios!$C$6 -> 36083.628 | J37: =J36*$B$9*Scenarios!$C$6 -> 36624.882 | K37: =K36*$B$9*Scenarios!$C$6 -> 37174.255 | ... Q37: =Q36*$B$9*Scenarios!$C$6 -> 40647.939
A38: Sign-on paid | C38: =$B$12*$B$13 -> 50000 | D38: =$B$12*$B$14 -> 50000 | E38: =$B$12*$B$15 -> 0 | F38: 0 | G38: 0 | H38: 0 | I38: 0 | J38: 0 | K38: 0 | L38: 0 | M38: 0 | N38: 0 | O38: 0 | P38: 0 | Q38: 0
A40: GRANT LEDGER — dollar value vesting each year, one row per grant | S40: Grant year | T40: Grant value ($) | U40: Shares granted | V40: Shares vested in horizon | W40: Unvested shares
A41: Initial grant | C41: =IF(AND(C$33-$S41+1-$B$22>=1,C$33-$S41+1-$B$22<=8),INDEX($C$26:$J$26,1,C$33-$S41+1-$B$22),0)*$U41*C$34 -> 0 | D41: =IF(AND(D$33-$S41+1-$B$22>=1,D$33-$S41+1-$B$22<=8),INDEX($C$26:$J$26,1,D$33-$S41+1-$B$22),0)*$U41*D$34 -> 160000 | E41: =IF(AND(E$33-$S41+1-$B$22>=1,E$33-$S41+1-$B$22<=8),INDEX($C$26:$J$26,1,E$33-$S41+1-$B$22),0)*$U41*E$34 -> 112000 | F41: =IF(AND(F$33-$S41+1-$B$22>=1,F$33-$S41+1-$B$22<=8),INDEX($C$26:$J$26,1,F$33-$S41+1-$B$22),0)*$U41*F$34 -> 80000 | G41: =IF(AND(G$33-$S41+1-$B$22>=1,G$33-$S41+1-$B$22<=8),INDEX($C$26:$J$26,1,G$33-$S41+1-$B$22),0)*$U41*G$34 -> 48000 | H41: =IF(AND(H$33-$S41+1-$B$22>=1,H$33-$S41+1-$B$22<=8),INDEX($C$26:$J$26,1,H$33-$S41+1-$B$22),0)*$U41*H$34 -> 0 | I41: =IF(AND(I$33-$S41+1-$B$22>=1,I$33-$S41+1-$B$22<=8),INDEX($C$26:$J$26,1,I$33-$S41+1-$B$22),0)*$U41*I$34 -> 0 | J41: =IF(AND(J$33-$S41+1-$B$22>=1,J$33-$S41+1-$B$22<=8),INDEX($C$26:$J$26,1,J$33-$S41+1-$B$22),0)*$U41*J$34 -> 0 | ... Q41: =IF(AND(Q$33-$S41+1-$B$22>=1,Q$33-$S41+1-$B$22<=8),INDEX($C$26:$J$26,1,Q$33-$S41+1-$B$22),0)*$U41*Q$34 -> 0 | S41: =$B$6 -> 2026 | T41: =$B$18 -> 400000 | U41: =IFERROR(T41/$B$17,0) -> 2666.6667 | V41: =SUMPRODUCT(($C$25:$J$25<=$Q$33-$S41+1-$B$22)*$C$26:$J$26)*$U41 -> 2666.6667 | W41: =$U41-$V41 -> 0
A42: Refresher grant 1 | C42: =IF(AND(C$33-$S42+1-$B$22>=1,C$33-$S42+1-$B$22<=8),INDEX($C$27:$J$27,1,C$33-$S42+1-$B$22),0)*$U42*C$34 -> 0 | D42: =IF(AND(D$33-$S42+1-$B$22>=1,D$33-$S42+1-$B$22<=8),INDEX($C$27:$J$27,1,D$33-$S42+1-$B$22),0)*$U42*D$34 -> 0 | E42: =IF(AND(E$33-$S42+1-$B$22>=1,E$33-$S42+1-$B$22<=8),INDEX($C$27:$J$27,1,E$33-$S42+1-$B$22),0)*$U42*E$34 -> 37500 | F42: =IF(AND(F$33-$S42+1-$B$22>=1,F$33-$S42+1-$B$22<=8),INDEX($C$27:$J$27,1,F$33-$S42+1-$B$22),0)*$U42*F$34 -> 37500 | G42: =IF(AND(G$33-$S42+1-$B$22>=1,G$33-$S42+1-$B$22<=8),INDEX($C$27:$J$27,1,G$33-$S42+1-$B$22),0)*$U42*G$34 -> 37500 | H42: =IF(AND(H$33-$S42+1-$B$22>=1,H$33-$S42+1-$B$22<=8),INDEX($C$27:$J$27,1,H$33-$S42+1-$B$22),0)*$U42*H$34 -> 37500 | I42: =IF(AND(I$33-$S42+1-$B$22>=1,I$33-$S42+1-$B$22<=8),INDEX($C$27:$J$27,1,I$33-$S42+1-$B$22),0)*$U42*I$34 -> 0 | J42: =IF(AND(J$33-$S42+1-$B$22>=1,J$33-$S42+1-$B$22<=8),INDEX($C$27:$J$27,1,J$33-$S42+1-$B$22),0)*$U42*J$34 -> 0 | ... Q42: =IF(AND(Q$33-$S42+1-$B$22>=1,Q$33-$S42+1-$B$22<=8),INDEX($C$27:$J$27,1,Q$33-$S42+1-$B$22),0)*$U42*Q$34 -> 0 | S42: =$B$20+0 -> 2027 | T42: =IF($S42>$B$20+Scenarios!$C$8-1,0,$B$19*(1+$B$21*Scenarios!$C$7)^0) -> 150000 | U42: =IFERROR($T42/INDEX($C$34:$Q$34,1,MATCH($S42,$C$33:$Q$33,0)),0) -> 1000 | V42: =SUMPRODUCT(($C$25:$J$25<=$Q$33-$S42+1-$B$22)*$C$27:$J$27)*$U42 -> 1000 | W42: =$U42-$V42 -> 0
A43: Refresher grant 2 | C43: =IF(AND(C$33-$S43+1-$B$22>=1,C$33-$S43+1-$B$22<=8),INDEX($C$27:$J$27,1,C$33-$S43+1-$B$22),0)*$U43*C$34 -> 0 | D43: =IF(AND(D$33-$S43+1-$B$22>=1,D$33-$S43+1-$B$22<=8),INDEX($C$27:$J$27,1,D$33-$S43+1-$B$22),0)*$U43*D$34 -> 0 | E43: =IF(AND(E$33-$S43+1-$B$22>=1,E$33-$S43+1-$B$22<=8),INDEX($C$27:$J$27,1,E$33-$S43+1-$B$22),0)*$U43*E$34 -> 0 | F43: =IF(AND(F$33-$S43+1-$B$22>=1,F$33-$S43+1-$B$22<=8),INDEX($C$27:$J$27,1,F$33-$S43+1-$B$22),0)*$U43*F$34 -> 37500 | G43: =IF(AND(G$33-$S43+1-$B$22>=1,G$33-$S43+1-$B$22<=8),INDEX($C$27:$J$27,1,G$33-$S43+1-$B$22),0)*$U43*G$34 -> 37500 | H43: =IF(AND(H$33-$S43+1-$B$22>=1,H$33-$S43+1-$B$22<=8),INDEX($C$27:$J$27,1,H$33-$S43+1-$B$22),0)*$U43*H$34 -> 37500 | I43: =IF(AND(I$33-$S43+1-$B$22>=1,I$33-$S43+1-$B$22<=8),INDEX($C$27:$J$27,1,I$33-$S43+1-$B$22),0)*$U43*I$34 -> 37500 | J43: =IF(AND(J$33-$S43+1-$B$22>=1,J$33-$S43+1-$B$22<=8),INDEX($C$27:$J$27,1,J$33-$S43+1-$B$22),0)*$U43*J$34 -> 0 | ... Q43: =IF(AND(Q$33-$S43+1-$B$22>=1,Q$33-$S43+1-$B$22<=8),INDEX($C$27:$J$27,1,Q$33-$S43+1-$B$22),0)*$U43*Q$34 -> 0 | S43: =$B$20+1 -> 2028 | T43: =IF($S43>$B$20+Scenarios!$C$8-1,0,$B$19*(1+$B$21*Scenarios!$C$7)^1) -> 150000 | U43: =IFERROR($T43/INDEX($C$34:$Q$34,1,MATCH($S43,$C$33:$Q$33,0)),0) -> 1000 | V43: =SUMPRODUCT(($C$25:$J$25<=$Q$33-$S43+1-$B$22)*$C$27:$J$27)*$U43 -> 1000 | W43: =$U43-$V43 -> 0
...

Sheet Offer_2
A1: OFFER 2
A2: Blue = you edit. Black = formula, do not edit. Green = link to another tab. Yellow = key assumption.
A3: INPUTS
A4: Company name | B4: Company B
A5: Ticker | B5: TICKB
A6: Start calendar year | B6: 2026
A7: Base salary at start | B7: 210000
A8: Merit increase %/yr | B8: 0.03
A9: Bonus target % of base | B9: 0.2
A10: Bonus basis (Current or Prior) | B10: Current
A11: Bonus paid in Year 1? (Yes/No) | B11: No
A12: Sign-on total | B12: 75000
A13: Sign-on % paid Year 1 | B13: 0.5
A14: Sign-on % paid Year 2 | B14: 0.5
A15: Sign-on % paid Year 3 | B15: 0
A16: Sign-on check (must equal 100%) | B16: =SUM(B13:B15) -> 1 | C16: =IF(ROUND(B16,6)=1,"OK","ERROR - must total 100%") -> OK
A17: Grant-date share price | B17: 400
A18: Initial grant value ($) | B18: 350000
A19: Refresher value, first grant ($) | B19: 120000
A20: First refresher calendar year | B20: 2027
A21: Refresher grant growth %/yr | B21: 0.03
A22: First vest timing (0 = grant year, 1 = year after) | B22: 1
A23: Share price is entered manually. Replace with a market data lookup in the web app. The original workbook vested in the grant year itself (offset 0); real grants usually vest a year later (offset 1).
A24: VESTING SCHEDULES — % of the grant that vests in each year AFTER the grant date
A25: Years after grant | C25: 1 | D25: 2 | E25: 3 | F25: 4 | G25: 5 | H25: 6 | I25: 7 | J25: 8 | K25: Total
A26: Initial grant | C26: 0.25 | D26: 0.25 | E26: 0.25 | F26: 0.25 | G26: 0 | H26: 0 | I26: 0 | J26: 0 | K26: =SUM(C26:J26) -> 1 | L26: =IF(ROUND(K26,6)=1,"OK","ERROR - must total 100%") -> OK
A27: Refresher grants | C27: 0.25 | D27: 0.25 | E27: 0.25 | F27: 0.25 | G27: 0 | H27: 0 | I27: 0 | J27: 0 | K27: =SUM(C27:J27) -> 1 | L27: =IF(ROUND(K27,6)=1,"OK","ERROR - must total 100%") -> OK
A28: Annual granularity. Sub-annual (quarterly/monthly) vesting and cliffs are handled in the web app, not here.
A31: SCENARIO: CONSERVATIVE | B31: =Scenarios!C$3 -> Conservative
A32: Year index | C32: 1 | D32: 2 | E32: 3 | F32: 4 | G32: 5 | H32: 6 | I32: 7 | J32: 8 | K32: 9 | L32: 10 | M32: 11 | N32: 12 | O32: 13 | P32: 14 | Q32: 15
A33: Calendar year | C33: =$B$6 -> 2026 | D33: =C33+1 -> 2027 | E33: =D33+1 -> 2028 | F33: =E33+1 -> 2029 | G33: =F33+1 -> 2030 | H33: =G33+1 -> 2031 | I33: =H33+1 -> 2032 | J33: =I33+1 -> 2033 | K33: =J33+1 -> 2034 | ... Q33: =P33+1 -> 2040
A34: Share price ($) | C34: =$B$17 -> 400 | D34: =C34*(1+Scenarios!$C$4) -> 400 | E34: =D34*(1+Scenarios!$C$4) -> 400 | F34: =E34*(1+Scenarios!$C$4) -> 400 | G34: =F34*(1+Scenarios!$C$4) -> 400 | H34: =G34*(1+Scenarios!$C$4) -> 400 | I34: =H34*(1+Scenarios!$C$4) -> 400 | J34: =I34*(1+Scenarios!$C$4) -> 400 | K34: =J34*(1+Scenarios!$C$4) -> 400 | ... Q34: =P34*(1+Scenarios!$C$4) -> 400
A35: Base salary | C35: =$B$7 -> 210000 | D35: =C35*(1+$B$8*Scenarios!$C$5) -> 213150 | E35: =D35*(1+$B$8*Scenarios!$C$5) -> 216347.25 | F35: =E35*(1+$B$8*Scenarios!$C$5) -> 219592.46 | G35: =F35*(1+$B$8*Scenarios!$C$5) -> 222886.35 | H35: =G35*(1+$B$8*Scenarios!$C$5) -> 226229.64 | I35: =H35*(1+$B$8*Scenarios!$C$5) -> 229623.09 | J35: =I35*(1+$B$8*Scenarios!$C$5) -> 233067.43 | K35: =J35*(1+$B$8*Scenarios!$C$5) -> 236563.44 | ... Q35: =P35*(1+$B$8*Scenarios!$C$5) -> 258668.7
A36: Bonus basis salary | C36: =IF($B$10="Prior",0,C35) -> 210000 | D36: =IF($B$10="Prior",C35,D35) -> 213150 | E36: =IF($B$10="Prior",D35,E35) -> 216347.25 | F36: =IF($B$10="Prior",E35,F35) -> 219592.46 | G36: =IF($B$10="Prior",F35,G35) -> 222886.35 | H36: =IF($B$10="Prior",G35,H35) -> 226229.64 | I36: =IF($B$10="Prior",H35,I35) -> 229623.09 | J36: =IF($B$10="Prior",I35,J35) -> 233067.43 | K36: =IF($B$10="Prior",J35,K35) -> 236563.44 | ... Q36: =IF($B$10="Prior",P35,Q35) -> 258668.7
A37: Annual bonus | C37: =IF($B$11="No",0,C36*$B$9*Scenarios!$C$6) -> 0 | D37: =D36*$B$9*Scenarios!$C$6 -> 31972.5 | E37: =E36*$B$9*Scenarios!$C$6 -> 32452.088 | F37: =F36*$B$9*Scenarios!$C$6 -> 32938.869 | G37: =G36*$B$9*Scenarios!$C$6 -> 33432.952 | H37: =H36*$B$9*Scenarios!$C$6 -> 33934.446 | I37: =I36*$B$9*Scenarios!$C$6 -> 34443.463 | J37: =J36*$B$9*Scenarios!$C$6 -> 34960.115 | K37: =K36*$B$9*Scenarios!$C$6 -> 35484.516 | ... Q37: =Q36*$B$9*Scenarios!$C$6 -> 38800.306
A38: Sign-on paid | C38: =$B$12*$B$13 -> 37500 | D38: =$B$12*$B$14 -> 37500 | E38: =$B$12*$B$15 -> 0 | F38: 0 | G38: 0 | H38: 0 | I38: 0 | J38: 0 | K38: 0 | L38: 0 | M38: 0 | N38: 0 | O38: 0 | P38: 0 | Q38: 0
A40: GRANT LEDGER — dollar value vesting each year, one row per grant | S40: Grant year | T40: Grant value ($) | U40: Shares granted | V40: Shares vested in horizon | W40: Unvested shares
A41: Initial grant | C41: =IF(AND(C$33-$S41+1-$B$22>=1,C$33-$S41+1-$B$22<=8),INDEX($C$26:$J$26,1,C$33-$S41+1-$B$22),0)*$U41*C$34 -> 0 | D41: =IF(AND(D$33-$S41+1-$B$22>=1,D$33-$S41+1-$B$22<=8),INDEX($C$26:$J$26,1,D$33-$S41+1-$B$22),0)*$U41*D$34 -> 87500 | E41: =IF(AND(E$33-$S41+1-$B$22>=1,E$33-$S41+1-$B$22<=8),INDEX($C$26:$J$26,1,E$33-$S41+1-$B$22),0)*$U41*E$34 -> 87500 | F41: =IF(AND(F$33-$S41+1-$B$22>=1,F$33-$S41+1-$B$22<=8),INDEX($C$26:$J$26,1,F$33-$S41+1-$B$22),0)*$U41*F$34 -> 87500 | G41: =IF(AND(G$33-$S41+1-$B$22>=1,G$33-$S41+1-$B$22<=8),INDEX($C$26:$J$26,1,G$33-$S41+1-$B$22),0)*$U41*G$34 -> 87500 | H41: =IF(AND(H$33-$S41+1-$B$22>=1,H$33-$S41+1-$B$22<=8),INDEX($C$26:$J$26,1,H$33-$S41+1-$B$22),0)*$U41*H$34 -> 0 | I41: =IF(AND(I$33-$S41+1-$B$22>=1,I$33-$S41+1-$B$22<=8),INDEX($C$26:$J$26,1,I$33-$S41+1-$B$22),0)*$U41*I$34 -> 0 | J41: =IF(AND(J$33-$S41+1-$B$22>=1,J$33-$S41+1-$B$22<=8),INDEX($C$26:$J$26,1,J$33-$S41+1-$B$22),0)*$U41*J$34 -> 0 | ... Q41: =IF(AND(Q$33-$S41+1-$B$22>=1,Q$33-$S41+1-$B$22<=8),INDEX($C$26:$J$26,1,Q$33-$S41+1-$B$22),0)*$U41*Q$34 -> 0 | S41: =$B$6 -> 2026 | T41: =$B$18 -> 350000 | U41: =IFERROR(T41/$B$17,0) -> 875 | V41: =SUMPRODUCT(($C$25:$J$25<=$Q$33-$S41+1-$B$22)*$C$26:$J$26)*$U41 -> 875 | W41: =$U41-$V41 -> 0
A42: Refresher grant 1 | C42: =IF(AND(C$33-$S42+1-$B$22>=1,C$33-$S42+1-$B$22<=8),INDEX($C$27:$J$27,1,C$33-$S42+1-$B$22),0)*$U42*C$34 -> 0 | D42: =IF(AND(D$33-$S42+1-$B$22>=1,D$33-$S42+1-$B$22<=8),INDEX($C$27:$J$27,1,D$33-$S42+1-$B$22),0)*$U42*D$34 -> 0 | E42: =IF(AND(E$33-$S42+1-$B$22>=1,E$33-$S42+1-$B$22<=8),INDEX($C$27:$J$27,1,E$33-$S42+1-$B$22),0)*$U42*E$34 -> 30000 | F42: =IF(AND(F$33-$S42+1-$B$22>=1,F$33-$S42+1-$B$22<=8),INDEX($C$27:$J$27,1,F$33-$S42+1-$B$22),0)*$U42*F$34 -> 30000 | G42: =IF(AND(G$33-$S42+1-$B$22>=1,G$33-$S42+1-$B$22<=8),INDEX($C$27:$J$27,1,G$33-$S42+1-$B$22),0)*$U42*G$34 -> 30000 | H42: =IF(AND(H$33-$S42+1-$B$22>=1,H$33-$S42+1-$B$22<=8),INDEX($C$27:$J$27,1,H$33-$S42+1-$B$22),0)*$U42*H$34 -> 30000 | I42: =IF(AND(I$33-$S42+1-$B$22>=1,I$33-$S42+1-$B$22<=8),INDEX($C$27:$J$27,1,I$33-$S42+1-$B$22),0)*$U42*I$34 -> 0 | J42: =IF(AND(J$33-$S42+1-$B$22>=1,J$33-$S42+1-$B$22<=8),INDEX($C$27:$J$27,1,J$33-$S42+1-$B$22),0)*$U42*J$34 -> 0 | ... Q42: =IF(AND(Q$33-$S42+1-$B$22>=1,Q$33-$S42+1-$B$22<=8),INDEX($C$27:$J$27,1,Q$33-$S42+1-$B$22),0)*$U42*Q$34 -> 0 | S42: =$B$20+0 -> 2027 | T42: =IF($S42>$B$20+Scenarios!$C$8-1,0,$B$19*(1+$B$21*Scenarios!$C$7)^0) -> 120000 | U42: =IFERROR($T42/INDEX($C$34:$Q$34,1,MATCH($S42,$C$33:$Q$33,0)),0) -> 300 | V42: =SUMPRODUCT(($C$25:$J$25<=$Q$33-$S42+1-$B$22)*$C$27:$J$27)*$U42 -> 300 | W42: =$U42-$V42 -> 0
A43: Refresher grant 2 | C43: =IF(AND(C$33-$S43+1-$B$22>=1,C$33-$S43+1-$B$22<=8),INDEX($C$27:$J$27,1,C$33-$S43+1-$B$22),0)*$U43*C$34 -> 0 | D43: =IF(AND(D$33-$S43+1-$B$22>=1,D$33-$S43+1-$B$22<=8),INDEX($C$27:$J$27,1,D$33-$S43+1-$B$22),0)*$U43*D$34 -> 0 | E43: =IF(AND(E$33-$S43+1-$B$22>=1,E$33-$S43+1-$B$22<=8),INDEX($C$27:$J$27,1,E$33-$S43+1-$B$22),0)*$U43*E$34 -> 0 | F43: =IF(AND(F$33-$S43+1-$B$22>=1,F$33-$S43+1-$B$22<=8),INDEX($C$27:$J$27,1,F$33-$S43+1-$B$22),0)*$U43*F$34 -> 30000 | G43: =IF(AND(G$33-$S43+1-$B$22>=1,G$33-$S43+1-$B$22<=8),INDEX($C$27:$J$27,1,G$33-$S43+1-$B$22),0)*$U43*G$34 -> 30000 | H43: =IF(AND(H$33-$S43+1-$B$22>=1,H$33-$S43+1-$B$22<=8),INDEX($C$27:$J$27,1,H$33-$S43+1-$B$22),0)*$U43*H$34 -> 30000 | I43: =IF(AND(I$33-$S43+1-$B$22>=1,I$33-$S43+1-$B$22<=8),INDEX($C$27:$J$27,1,I$33-$S43+1-$B$22),0)*$U43*I$34 -> 30000 | J43: =IF(AND(J$33-$S43+1-$B$22>=1,J$33-$S43+1-$B$22<=8),INDEX($C$27:$J$27,1,J$33-$S43+1-$B$22),0)*$U43*J$34 -> 0 | ... Q43: =IF(AND(Q$33-$S43+1-$B$22>=1,Q$33-$S43+1-$B$22<=8),INDEX($C$27:$J$27,1,Q$33-$S43+1-$B$22),0)*$U43*Q$34 -> 0 | S43: =$B$20+1 -> 2028 | T43: =IF($S43>$B$20+Scenarios!$C$8-1,0,$B$19*(1+$B$21*Scenarios!$C$7)^1) -> 120000 | U43: =IFERROR($T43/INDEX($C$34:$Q$34,1,MATCH($S43,$C$33:$Q$33,0)),0) -> 300 | V43: =SUMPRODUCT(($C$25:$J$25<=$Q$33-$S43+1-$B$22)*$C$27:$J$27)*$U43 -> 300 | W43: =$U43-$V43 -> 0
...

Sheet Offer_3
A1: OFFER 3
A2: Blue = you edit. Black = formula, do not edit. Green = link to another tab. Yellow = key assumption.
A3: INPUTS
A4: Company name | B4: Company C
A5: Ticker | B5: TICKC
A6: Start calendar year | B6: 2026
A7: Base salary at start | B7: 190000
A8: Merit increase %/yr | B8: 0.03
A9: Bonus target % of base | B9: 0.15
A10: Bonus basis (Current or Prior) | B10: Current
A11: Bonus paid in Year 1? (Yes/No) | B11: No
A12: Sign-on total | B12: 50000
A13: Sign-on % paid Year 1 | B13: 0.5
A14: Sign-on % paid Year 2 | B14: 0.5
A15: Sign-on % paid Year 3 | B15: 0
A16: Sign-on check (must equal 100%) | B16: =SUM(B13:B15) -> 1 | C16: =IF(ROUND(B16,6)=1,"OK","ERROR - must total 100%") -> OK
A17: Grant-date share price | B17: 180
A18: Initial grant value ($) | B18: 500000
A19: Refresher value, first grant ($) | B19: 100000
A20: First refresher calendar year | B20: 2027
A21: Refresher grant growth %/yr | B21: 0.03
A22: First vest timing (0 = grant year, 1 = year after) | B22: 1
A23: Share price is entered manually. Replace with a market data lookup in the web app. The original workbook vested in the grant year itself (offset 0); real grants usually vest a year later (offset 1).
A24: VESTING SCHEDULES — % of the grant that vests in each year AFTER the grant date
A25: Years after grant | C25: 1 | D25: 2 | E25: 3 | F25: 4 | G25: 5 | H25: 6 | I25: 7 | J25: 8 | K25: Total
A26: Initial grant | C26: 0.2 | D26: 0.2 | E26: 0.2 | F26: 0.2 | G26: 0.2 | H26: 0 | I26: 0 | J26: 0 | K26: =SUM(C26:J26) -> 1 | L26: =IF(ROUND(K26,6)=1,"OK","ERROR - must total 100%") -> OK
A27: Refresher grants | C27: 0.2 | D27: 0.2 | E27: 0.2 | F27: 0.2 | G27: 0.2 | H27: 0 | I27: 0 | J27: 0 | K27: =SUM(C27:J27) -> 1 | L27: =IF(ROUND(K27,6)=1,"OK","ERROR - must total 100%") -> OK
A28: Annual granularity. Sub-annual (quarterly/monthly) vesting and cliffs are handled in the web app, not here.
A31: SCENARIO: CONSERVATIVE | B31: =Scenarios!C$3 -> Conservative
A32: Year index | C32: 1 | D32: 2 | E32: 3 | F32: 4 | G32: 5 | H32: 6 | I32: 7 | J32: 8 | K32: 9 | L32: 10 | M32: 11 | N32: 12 | O32: 13 | P32: 14 | Q32: 15
A33: Calendar year | C33: =$B$6 -> 2026 | D33: =C33+1 -> 2027 | E33: =D33+1 -> 2028 | F33: =E33+1 -> 2029 | G33: =F33+1 -> 2030 | H33: =G33+1 -> 2031 | I33: =H33+1 -> 2032 | J33: =I33+1 -> 2033 | K33: =J33+1 -> 2034 | ... Q33: =P33+1 -> 2040
A34: Share price ($) | C34: =$B$17 -> 180 | D34: =C34*(1+Scenarios!$C$4) -> 180 | E34: =D34*(1+Scenarios!$C$4) -> 180 | F34: =E34*(1+Scenarios!$C$4) -> 180 | G34: =F34*(1+Scenarios!$C$4) -> 180 | H34: =G34*(1+Scenarios!$C$4) -> 180 | I34: =H34*(1+Scenarios!$C$4) -> 180 | J34: =I34*(1+Scenarios!$C$4) -> 180 | K34: =J34*(1+Scenarios!$C$4) -> 180 | ... Q34: =P34*(1+Scenarios!$C$4) -> 180
A35: Base salary | C35: =$B$7 -> 190000 | D35: =C35*(1+$B$8*Scenarios!$C$5) -> 192850 | E35: =D35*(1+$B$8*Scenarios!$C$5) -> 195742.75 | F35: =E35*(1+$B$8*Scenarios!$C$5) -> 198678.89 | G35: =F35*(1+$B$8*Scenarios!$C$5) -> 201659.07 | H35: =G35*(1+$B$8*Scenarios!$C$5) -> 204683.96 | I35: =H35*(1+$B$8*Scenarios!$C$5) -> 207754.22 | J35: =I35*(1+$B$8*Scenarios!$C$5) -> 210870.53 | K35: =J35*(1+$B$8*Scenarios!$C$5) -> 214033.59 | ... Q35: =P35*(1+$B$8*Scenarios!$C$5) -> 234033.59
A36: Bonus basis salary | C36: =IF($B$10="Prior",0,C35) -> 190000 | D36: =IF($B$10="Prior",C35,D35) -> 192850 | E36: =IF($B$10="Prior",D35,E35) -> 195742.75 | F36: =IF($B$10="Prior",E35,F35) -> 198678.89 | G36: =IF($B$10="Prior",F35,G35) -> 201659.07 | H36: =IF($B$10="Prior",G35,H35) -> 204683.96 | I36: =IF($B$10="Prior",H35,I35) -> 207754.22 | J36: =IF($B$10="Prior",I35,J35) -> 210870.53 | K36: =IF($B$10="Prior",J35,K35) -> 214033.59 | ... Q36: =IF($B$10="Prior",P35,Q35) -> 234033.59
A37: Annual bonus | C37: =IF($B$11="No",0,C36*$B$9*Scenarios!$C$6) -> 0 | D37: =D36*$B$9*Scenarios!$C$6 -> 21695.625 | E37: =E36*$B$9*Scenarios!$C$6 -> 22021.059 | F37: =F36*$B$9*Scenarios!$C$6 -> 22351.375 | G37: =G36*$B$9*Scenarios!$C$6 -> 22686.646 | H37: =H36*$B$9*Scenarios!$C$6 -> 23026.946 | I37: =I36*$B$9*Scenarios!$C$6 -> 23372.35 | J37: =J36*$B$9*Scenarios!$C$6 -> 23722.935 | K37: =K36*$B$9*Scenarios!$C$6 -> 24078.779 | ... Q37: =Q36*$B$9*Scenarios!$C$6 -> 26328.779
A38: Sign-on paid | C38: =$B$12*$B$13 -> 25000 | D38: =$B$12*$B$14 -> 25000 | E38: =$B$12*$B$15 -> 0 | F38: 0 | G38: 0 | H38: 0 | I38: 0 | J38: 0 | K38: 0 | L38: 0 | M38: 0 | N38: 0 | O38: 0 | P38: 0 | Q38: 0
A40: GRANT LEDGER — dollar value vesting each year, one row per grant | S40: Grant year | T40: Grant value ($) | U40: Shares granted | V40: Shares vested in horizon | W40: Unvested shares
A41: Initial grant | C41: =IF(AND(C$33-$S41+1-$B$22>=1,C$33-$S41+1-$B$22<=8),INDEX($C$26:$J$26,1,C$33-$S41+1-$B$22),0)*$U41*C$34 -> 0 | D41: =IF(AND(D$33-$S41+1-$B$22>=1,D$33-$S41+1-$B$22<=8),INDEX($C$26:$J$26,1,D$33-$S41+1-$B$22),0)*$U41*D$34 -> 100000 | E41: =IF(AND(E$33-$S41+1-$B$22>=1,E$33-$S41+1-$B$22<=8),INDEX($C$26:$J$26,1,E$33-$S41+1-$B$22),0)*$U41*E$34 -> 100000 | F41: =IF(AND(F$33-$S41+1-$B$22>=1,F$33-$S41+1-$B$22<=8),INDEX($C$26:$J$26,1,F$33-$S41+1-$B$22),0)*$U41*F$34 -> 100000 | G41: =IF(AND(G$33-$S41+1-$B$22>=1,G$33-$S41+1-$B$22<=8),INDEX($C$26:$J$26,1,G$33-$S41+1-$B$22),0)*$U41*G$34 -> 100000 | H41: =IF(AND(H$33-$S41+1-$B$22>=1,H$33-$S41+1-$B$22<=8),INDEX($C$26:$J$26,1,H$33-$S41+1-$B$22),0)*$U41*H$34 -> 100000 | I41: =IF(AND(I$33-$S41+1-$B$22>=1,I$33-$S41+1-$B$22<=8),INDEX($C$26:$J$26,1,I$33-$S41+1-$B$22),0)*$U41*I$34 -> 0 | J41: =IF(AND(J$33-$S41+1-$B$22>=1,J$33-$S41+1-$B$22<=8),INDEX($C$26:$J$26,1,J$33-$S41+1-$B$22),0)*$U41*J$34 -> 0 | ... Q41: =IF(AND(Q$33-$S41+1-$B$22>=1,Q$33-$S41+1-$B$22<=8),INDEX($C$26:$J$26,1,Q$33-$S41+1-$B$22),0)*$U41*Q$34 -> 0 | S41: =$B$6 -> 2026 | T41: =$B$18 -> 500000 | U41: =IFERROR(T41/$B$17,0) -> 2777.7778 | V41: =SUMPRODUCT(($C$25:$J$25<=$Q$33-$S41+1-$B$22)*$C$26:$J$26)*$U41 -> 2777.7778 | W41: =$U41-$V41 -> 0
A42: Refresher grant 1 | C42: =IF(AND(C$33-$S42+1-$B$22>=1,C$33-$S42+1-$B$22<=8),INDEX($C$27:$J$27,1,C$33-$S42+1-$B$22),0)*$U42*C$34 -> 0 | D42: =IF(AND(D$33-$S42+1-$B$22>=1,D$33-$S42+1-$B$22<=8),INDEX($C$27:$J$27,1,D$33-$S42+1-$B$22),0)*$U42*D$34 -> 0 | E42: =IF(AND(E$33-$S42+1-$B$22>=1,E$33-$S42+1-$B$22<=8),INDEX($C$27:$J$27,1,E$33-$S42+1-$B$22),0)*$U42*E$34 -> 20000 | F42: =IF(AND(F$33-$S42+1-$B$22>=1,F$33-$S42+1-$B$22<=8),INDEX($C$27:$J$27,1,F$33-$S42+1-$B$22),0)*$U42*F$34 -> 20000 | G42: =IF(AND(G$33-$S42+1-$B$22>=1,G$33-$S42+1-$B$22<=8),INDEX($C$27:$J$27,1,G$33-$S42+1-$B$22),0)*$U42*G$34 -> 20000 | H42: =IF(AND(H$33-$S42+1-$B$22>=1,H$33-$S42+1-$B$22<=8),INDEX($C$27:$J$27,1,H$33-$S42+1-$B$22),0)*$U42*H$34 -> 20000 | I42: =IF(AND(I$33-$S42+1-$B$22>=1,I$33-$S42+1-$B$22<=8),INDEX($C$27:$J$27,1,I$33-$S42+1-$B$22),0)*$U42*I$34 -> 20000 | J42: =IF(AND(J$33-$S42+1-$B$22>=1,J$33-$S42+1-$B$22<=8),INDEX($C$27:$J$27,1,J$33-$S42+1-$B$22),0)*$U42*J$34 -> 0 | ... Q42: =IF(AND(Q$33-$S42+1-$B$22>=1,Q$33-$S42+1-$B$22<=8),INDEX($C$27:$J$27,1,Q$33-$S42+1-$B$22),0)*$U42*Q$34 -> 0 | S42: =$B$20+0 -> 2027 | T42: =IF($S42>$B$20+Scenarios!$C$8-1,0,$B$19*(1+$B$21*Scenarios!$C$7)^0) -> 100000 | U42: =IFERROR($T42/INDEX($C$34:$Q$34,1,MATCH($S42,$C$33:$Q$33,0)),0) -> 555.55556 | V42: =SUMPRODUCT(($C$25:$J$25<=$Q$33-$S42+1-$B$22)*$C$27:$J$27)*$U42 -> 555.55556 | W42: =$U42-$V42 -> 0
A43: Refresher grant 2 | C43: =IF(AND(C$33-$S43+1-$B$22>=1,C$33-$S43+1-$B$22<=8),INDEX($C$27:$J$27,1,C$33-$S43+1-$B$22),0)*$U43*C$34 -> 0 | D43: =IF(AND(D$33-$S43+1-$B$22>=1,D$33-$S43+1-$B$22<=8),INDEX($C$27:$J$27,1,D$33-$S43+1-$B$22),0)*$U43*D$34 -> 0 | E43: =IF(AND(E$33-$S43+1-$B$22>=1,E$33-$S43+1-$B$22<=8),INDEX($C$27:$J$27,1,E$33-$S43+1-$B$22),0)*$U43*E$34 -> 0 | F43: =IF(AND(F$33-$S43+1-$B$22>=1,F$33-$S43+1-$B$22<=8),INDEX($C$27:$J$27,1,F$33-$S43+1-$B$22),0)*$U43*F$34 -> 20000 | G43: =IF(AND(G$33-$S43+1-$B$22>=1,G$33-$S43+1-$B$22<=8),INDEX($C$27:$J$27,1,G$33-$S43+1-$B$22),0)*$U43*G$34 -> 20000 | H43: =IF(AND(H$33-$S43+1-$B$22>=1,H$33-$S43+1-$B$22<=8),INDEX($C$27:$J$27,1,H$33-$S43+1-$B$22),0)*$U43*H$34 -> 20000 | I43: =IF(AND(I$33-$S43+1-$B$22>=1,I$33-$S43+1-$B$22<=8),INDEX($C$27:$J$27,1,I$33-$S43+1-$B$22),0)*$U43*I$34 -> 20000 | J43: =IF(AND(J$33-$S43+1-$B$22>=1,J$33-$S43+1-$B$22<=8),INDEX($C$27:$J$27,1,J$33-$S43+1-$B$22),0)*$U43*J$34 -> 20000 | ... Q43: =IF(AND(Q$33-$S43+1-$B$22>=1,Q$33-$S43+1-$B$22<=8),INDEX($C$27:$J$27,1,Q$33-$S43+1-$B$22),0)*$U43*Q$34 -> 0 | S43: =$B$20+1 -> 2028 | T43: =IF($S43>$B$20+Scenarios!$C$8-1,0,$B$19*(1+$B$21*Scenarios!$C$7)^1) -> 100000 | U43: =IFERROR($T43/INDEX($C$34:$Q$34,1,MATCH($S43,$C$33:$Q$33,0)),0) -> 555.55556 | V43: =SUMPRODUCT(($C$25:$J$25<=$Q$33-$S43+1-$B$22)*$C$27:$J$27)*$U43 -> 555.55556 | W43: =$U43-$V43 -> 0
...

Sheet Current_Comp
A1: CURRENT COMPENSATION (BASELINE)
A2: Blue = you edit. Black = formula, do not edit. Green = link to another tab. Yellow = key assumption.
A3: INPUTS
A4: Company name | B4: Current employer
A5: Ticker | B5: n/a
A6: Start calendar year | B6: 2026
A7: Base salary at start | B7: 275000
A8: Merit increase %/yr | B8: 0.03
A9: Bonus target % of base | B9: 0.22
A10: Bonus basis (Current or Prior) | B10: Current
A11: Bonus paid in Year 1? (Yes/No) | B11: Yes
A12: Sign-on total | B12: 0
A13: Sign-on % paid Year 1 | B13: 0
A14: Sign-on % paid Year 2 | B14: 0
A15: Sign-on % paid Year 3 | B15: 0
A16: Sign-on check (must equal 100%) | B16: =SUM(B13:B15) -> 0 | C16: =IF(ROUND(B16,6)=1,"OK","ERROR - must total 100%") -> ERROR - must total 100%
A17: Grant-date share price | B17: 1
A18: Initial grant value ($) | B18: 0
A19: Refresher value, first grant ($) | B19: 0
A20: First refresher calendar year | B20: 2027
A21: Refresher grant growth %/yr | B21: 0
A22: First vest timing (0 = grant year, 1 = year after) | B22: 1
A23: Share price is entered manually. Replace with a market data lookup in the web app. The original workbook vested in the grant year itself (offset 0); real grants usually vest a year later (offset 1).
A24: VESTING SCHEDULES — % of the grant that vests in each year AFTER the grant date
A25: Years after grant | C25: 1 | D25: 2 | E25: 3 | F25: 4 | G25: 5 | H25: 6 | I25: 7 | J25: 8 | K25: Total
A26: Initial grant | C26: 0.25 | D26: 0.25 | E26: 0.25 | F26: 0.25 | G26: 0 | H26: 0 | I26: 0 | J26: 0 | K26: =SUM(C26:J26) -> 1 | L26: =IF(ROUND(K26,6)=1,"OK","ERROR - must total 100%") -> OK
A27: Refresher grants | C27: 0.25 | D27: 0.25 | E27: 0.25 | F27: 0.25 | G27: 0 | H27: 0 | I27: 0 | J27: 0 | K27: =SUM(C27:J27) -> 1 | L27: =IF(ROUND(K27,6)=1,"OK","ERROR - must total 100%") -> OK
A28: Annual granularity. Sub-annual (quarterly/monthly) vesting and cliffs are handled in the web app, not here.
A31: SCENARIO: CONSERVATIVE | B31: =Scenarios!C$3 -> Conservative
A32: Year index | C32: 1 | D32: 2 | E32: 3 | F32: 4 | G32: 5 | H32: 6 | I32: 7 | J32: 8 | K32: 9 | L32: 10 | M32: 11 | N32: 12 | O32: 13 | P32: 14 | Q32: 15
A33: Calendar year | C33: =$B$6 -> 2026 | D33: =C33+1 -> 2027 | E33: =D33+1 -> 2028 | F33: =E33+1 -> 2029 | G33: =F33+1 -> 2030 | H33: =G33+1 -> 2031 | I33: =H33+1 -> 2032 | J33: =I33+1 -> 2033 | K33: =J33+1 -> 2034 | ... Q33: =P33+1 -> 2040
A34: Share price ($) | C34: =$B$17 -> 1 | D34: =C34*(1+Scenarios!$C$4) -> 1 | E34: =D34*(1+Scenarios!$C$4) -> 1 | F34: =E34*(1+Scenarios!$C$4) -> 1 | G34: =F34*(1+Scenarios!$C$4) -> 1 | H34: =G34*(1+Scenarios!$C$4) -> 1 | I34: =H34*(1+Scenarios!$C$4) -> 1 | J34: =I34*(1+Scenarios!$C$4) -> 1 | K34: =J34*(1+Scenarios!$C$4) -> 1 | ... Q34: =P34*(1+Scenarios!$C$4) -> 1
A35: Base salary | C35: =$B$7 -> 275000 | D35: =C35*(1+$B$8*Scenarios!$C$5) -> 279125 | E35: =D35*(1+$B$8*Scenarios!$C$5) -> 283311.88 | F35: =E35*(1+$B$8*Scenarios!$C$5) -> 287561.55 | G35: =F35*(1+$B$8*Scenarios!$C$5) -> 291874.98 | H35: =G35*(1+$B$8*Scenarios!$C$5) -> 296253.1 | I35: =H35*(1+$B$8*Scenarios!$C$5) -> 300696.9 | J35: =I35*(1+$B$8*Scenarios!$C$5) -> 305207.35 | K35: =J35*(1+$B$8*Scenarios!$C$5) -> 309785.46 | ... Q35: =P35*(1+$B$8*Scenarios!$C$5) -> 338732.83
A36: Bonus basis salary | C36: =IF($B$10="Prior",0,C35) -> 275000 | D36: =IF($B$10="Prior",C35,D35) -> 279125 | E36: =IF($B$10="Prior",D35,E35) -> 283311.88 | F36: =IF($B$10="Prior",E35,F35) -> 287561.55 | G36: =IF($B$10="Prior",F35,G35) -> 291874.98 | H36: =IF($B$10="Prior",G35,H35) -> 296253.1 | I36: =IF($B$10="Prior",H35,I35) -> 300696.9 | J36: =IF($B$10="Prior",I35,J35) -> 305207.35 | K36: =IF($B$10="Prior",J35,K35) -> 309785.46 | ... Q36: =IF($B$10="Prior",P35,Q35) -> 338732.83
A37: Annual bonus | C37: =IF($B$11="No",0,C36*$B$9*Scenarios!$C$6) -> 45375 | D37: =D36*$B$9*Scenarios!$C$6 -> 46055.625 | E37: =E36*$B$9*Scenarios!$C$6 -> 46746.459 | F37: =F36*$B$9*Scenarios!$C$6 -> 47447.656 | G37: =G36*$B$9*Scenarios!$C$6 -> 48159.371 | H37: =H36*$B$9*Scenarios!$C$6 -> 48881.762 | I37: =I36*$B$9*Scenarios!$C$6 -> 49614.988 | J37: =J36*$B$9*Scenarios!$C$6 -> 50359.213 | K37: =K36*$B$9*Scenarios!$C$6 -> 51114.601 | ... Q37: =Q36*$B$9*Scenarios!$C$6 -> 55890.916
A38: Sign-on paid | C38: =$B$12*$B$13 -> 0 | D38: =$B$12*$B$14 -> 0 | E38: =$B$12*$B$15 -> 0 | F38: 0 | G38: 0 | H38: 0 | I38: 0 | J38: 0 | K38: 0 | L38: 0 | M38: 0 | N38: 0 | O38: 0 | P38: 0 | Q38: 0
A40: GRANT LEDGER — dollar value vesting each year, one row per grant | S40: Grant year | T40: Grant value ($) | U40: Shares granted | V40: Shares vested in horizon | W40: Unvested shares
A41: Initial grant | C41: =IF(AND(C$33-$S41+1-$B$22>=1,C$33-$S41+1-$B$22<=8),INDEX($C$26:$J$26,1,C$33-$S41+1-$B$22),0)*$U41*C$34 -> 0 | D41: =IF(AND(D$33-$S41+1-$B$22>=1,D$33-$S41+1-$B$22<=8),INDEX($C$26:$J$26,1,D$33-$S41+1-$B$22),0)*$U41*D$34 -> 0 | E41: =IF(AND(E$33-$S41+1-$B$22>=1,E$33-$S41+1-$B$22<=8),INDEX($C$26:$J$26,1,E$33-$S41+1-$B$22),0)*$U41*E$34 -> 0 | F41: =IF(AND(F$33-$S41+1-$B$22>=1,F$33-$S41+1-$B$22<=8),INDEX($C$26:$J$26,1,F$33-$S41+1-$B$22),0)*$U41*F$34 -> 0 | G41: =IF(AND(G$33-$S41+1-$B$22>=1,G$33-$S41+1-$B$22<=8),INDEX($C$26:$J$26,1,G$33-$S41+1-$B$22),0)*$U41*G$34 -> 0 | H41: =IF(AND(H$33-$S41+1-$B$22>=1,H$33-$S41+1-$B$22<=8),INDEX($C$26:$J$26,1,H$33-$S41+1-$B$22),0)*$U41*H$34 -> 0 | I41: =IF(AND(I$33-$S41+1-$B$22>=1,I$33-$S41+1-$B$22<=8),INDEX($C$26:$J$26,1,I$33-$S41+1-$B$22),0)*$U41*I$34 -> 0 | J41: =IF(AND(J$33-$S41+1-$B$22>=1,J$33-$S41+1-$B$22<=8),INDEX($C$26:$J$26,1,J$33-$S41+1-$B$22),0)*$U41*J$34 -> 0 | ... Q41: =IF(AND(Q$33-$S41+1-$B$22>=1,Q$33-$S41+1-$B$22<=8),INDEX($C$26:$J$26,1,Q$33-$S41+1-$B$22),0)*$U41*Q$34 -> 0 | S41: =$B$6 -> 2026 | T41: =$B$18 -> 0 | U41: =IFERROR(T41/$B$17,0) -> 0 | V41: =SUMPRODUCT(($C$25:$J$25<=$Q$33-$S41+1-$B$22)*$C$26:$J$26)*$U41 -> 0 | W41: =$U41-$V41 -> 0
A42: Refresher grant 1 | C42: =IF(AND(C$33-$S42+1-$B$22>=1,C$33-$S42+1-$B$22<=8),INDEX($C$27:$J$27,1,C$33-$S42+1-$B$22),0)*$U42*C$34 -> 0 | D42: =IF(AND(D$33-$S42+1-$B$22>=1,D$33-$S42+1-$B$22<=8),INDEX($C$27:$J$27,1,D$33-$S42+1-$B$22),0)*$U42*D$34 -> 0 | E42: =IF(AND(E$33-$S42+1-$B$22>=1,E$33-$S42+1-$B$22<=8),INDEX($C$27:$J$27,1,E$33-$S42+1-$B$22),0)*$U42*E$34 -> 0 | F42: =IF(AND(F$33-$S42+1-$B$22>=1,F$33-$S42+1-$B$22<=8),INDEX($C$27:$J$27,1,F$33-$S42+1-$B$22),0)*$U42*F$34 -> 0 | G42: =IF(AND(G$33-$S42+1-$B$22>=1,G$33-$S42+1-$B$22<=8),INDEX($C$27:$J$27,1,G$33-$S42+1-$B$22),0)*$U42*G$34 -> 0 | H42: =IF(AND(H$33-$S42+1-$B$22>=1,H$33-$S42+1-$B$22<=8),INDEX($C$27:$J$27,1,H$33-$S42+1-$B$22),0)*$U42*H$34 -> 0 | I42: =IF(AND(I$33-$S42+1-$B$22>=1,I$33-$S42+1-$B$22<=8),INDEX($C$27:$J$27,1,I$33-$S42+1-$B$22),0)*$U42*I$34 -> 0 | J42: =IF(AND(J$33-$S42+1-$B$22>=1,J$33-$S42+1-$B$22<=8),INDEX($C$27:$J$27,1,J$33-$S42+1-$B$22),0)*$U42*J$34 -> 0 | ... Q42: =IF(AND(Q$33-$S42+1-$B$22>=1,Q$33-$S42+1-$B$22<=8),INDEX($C$27:$J$27,1,Q$33-$S42+1-$B$22),0)*$U42*Q$34 -> 0 | S42: =$B$20+0 -> 2027 | T42: =IF($S42>$B$20+Scenarios!$C$8-1,0,$B$19*(1+$B$21*Scenarios!$C$7)^0) -> 0 | U42: =IFERROR($T42/INDEX($C$34:$Q$34,1,MATCH($S42,$C$33:$Q$33,0)),0) -> 0 | V42: =SUMPRODUCT(($C$25:$J$25<=$Q$33-$S42+1-$B$22)*$C$27:$J$27)*$U42 -> 0 | W42: =$U42-$V42 -> 0
A43: Refresher grant 2 | C43: =IF(AND(C$33-$S43+1-$B$22>=1,C$33-$S43+1-$B$22<=8),INDEX($C$27:$J$27,1,C$33-$S43+1-$B$22),0)*$U43*C$34 -> 0 | D43: =IF(AND(D$33-$S43+1-$B$22>=1,D$33-$S43+1-$B$22<=8),INDEX($C$27:$J$27,1,D$33-$S43+1-$B$22),0)*$U43*D$34 -> 0 | E43: =IF(AND(E$33-$S43+1-$B$22>=1,E$33-$S43+1-$B$22<=8),INDEX($C$27:$J$27,1,E$33-$S43+1-$B$22),0)*$U43*E$34 -> 0 | F43: =IF(AND(F$33-$S43+1-$B$22>=1,F$33-$S43+1-$B$22<=8),INDEX($C$27:$J$27,1,F$33-$S43+1-$B$22),0)*$U43*F$34 -> 0 | G43: =IF(AND(G$33-$S43+1-$B$22>=1,G$33-$S43+1-$B$22<=8),INDEX($C$27:$J$27,1,G$33-$S43+1-$B$22),0)*$U43*G$34 -> 0 | H43: =IF(AND(H$33-$S43+1-$B$22>=1,H$33-$S43+1-$B$22<=8),INDEX($C$27:$J$27,1,H$33-$S43+1-$B$22),0)*$U43*H$34 -> 0 | I43: =IF(AND(I$33-$S43+1-$B$22>=1,I$33-$S43+1-$B$22<=8),INDEX($C$27:$J$27,1,I$33-$S43+1-$B$22),0)*$U43*I$34 -> 0 | J43: =IF(AND(J$33-$S43+1-$B$22>=1,J$33-$S43+1-$B$22<=8),INDEX($C$27:$J$27,1,J$33-$S43+1-$B$22),0)*$U43*J$34 -> 0 | ... Q43: =IF(AND(Q$33-$S43+1-$B$22>=1,Q$33-$S43+1-$B$22<=8),INDEX($C$27:$J$27,1,Q$33-$S43+1-$B$22),0)*$U43*Q$34 -> 0 | S43: =$B$20+1 -> 2028 | T43: =IF($S43>$B$20+Scenarios!$C$8-1,0,$B$19*(1+$B$21*Scenarios!$C$7)^1) -> 0 | U43: =IFERROR($T43/INDEX($C$34:$Q$34,1,MATCH($S43,$C$33:$Q$33,0)),0) -> 0 | V43: =SUMPRODUCT(($C$25:$J$25<=$Q$33-$S43+1-$B$22)*$C$27:$J$27)*$U43 -> 0 | W43: =$U43-$V43 -> 0
...

Sheet Comparison
A1: OFFER COMPARISON
A2: Every figure on this tab is a link to an offer tab. Nothing here is an input.
A4: CUMULATIVE GROSS COMPENSATION BY SCENARIO
A5: Conservative | C5: Year 1 | D5: Year 3 | E5: Year 5 | F5: Year 10
A6: =Offer_1!$B$4 -> Company A | C6: =Offer_1!C61 -> 250000 | D6: =Offer_1!E61 -> 1086037.4 | E6: =Offer_1!G61 -> 1892478.2 | F6: =Offer_1!L61 -> 3560734.1
A7: =Offer_2!$B$4 -> Company B | C7: =Offer_2!C61 -> 247500 | D7: =Offer_2!E61 -> 983921.84 | E7: =Offer_2!G61 -> 1817772.5 | F7: =Offer_2!L61 -> 3458207.3
A8: =Offer_3!$B$4 -> Company C | C8: =Offer_3!C61 -> 215000 | D8: =Offer_3!E61 -> 892309.43 | E8: =Offer_3!G61 -> 1637685.4 | F8: =Offer_3!L61 -> 3190912.8
A9: =Current_Comp!$B$4 -> Current employer | C9: =Current_Comp!C61 -> 320375 | D9: =Current_Comp!E61 -> 975613.96 | E9: =Current_Comp!G61 -> 1650657.5 | F9: =Current_Comp!L61 -> 3428884.5
A12: Medium | C12: Year 1 | D12: Year 3 | E12: Year 5 | F12: Year 10
A13: =Offer_1!$B$4 -> Company A | C13: =Offer_1!C106 -> 250000 | D13: =Offer_1!E106 -> 1149733.4 | E13: =Offer_1!G106 -> 2068896.6 | F13: =Offer_1!L106 -> 4557443
A14: =Offer_2!$B$4 -> Company B | C14: =Offer_2!C106 -> 247500 | D14: =Offer_2!E106 -> 1037810.6 | E14: =Offer_2!G106 -> 1992285.5 | F14: =Offer_2!L106 -> 4332712.1
A15: =Offer_3!$B$4 -> Company C | C15: =Offer_3!C106 -> 215000 | D15: =Offer_3!E106 -> 939751.65 | E15: =Offer_3!G106 -> 1793749.1 | F15: =Offer_3!L106 -> 3922458.3
A16: =Current_Comp!$B$4 -> Current employer | C16: =Current_Comp!C106 -> 335500 | D16: =Current_Comp!E106 -> 1036996.9 | E16: =Current_Comp!G106 -> 1781215.1 | F16: =Current_Comp!L106 -> 3846131.5
A19: Aggressive | C19: Year 1 | D19: Year 3 | E19: Year 5 | F19: Year 10
A20: =Offer_1!$B$4 -> Company A | C20: =Offer_1!C151 -> 250000 | D20: =Offer_1!E151 -> 1220186.4 | E20: =Offer_1!G151 -> 2268776.5 | F20: =Offer_1!L151 -> 5196853.7
A21: =Offer_2!$B$4 -> Company B | C21: =Offer_2!C151 -> 247500 | D21: =Offer_2!E151 -> 1096812.8 | E21: =Offer_2!G151 -> 2193822.2 | F21: =Offer_2!L151 -> 4935107.7
A22: =Offer_3!$B$4 -> Company C | C22: =Offer_3!C151 -> 215000 | D22: =Offer_3!E151 -> 992416.27 | E22: =Offer_3!G151 -> 1978143.7 | F22: =Offer_3!L151 -> 4520234.4
A23: =Current_Comp!$B$4 -> Current employer | C23: =Current_Comp!C151 -> 350625 | D23: =Current_Comp!E151 -> 1099919.4 | E23: =Current_Comp!G151 -> 1918167.6 | F23: =Current_Comp!L151 -> 4308553.4
A26: MEDIUM SCENARIO — YEAR BY YEAR
A27: Calendar year | C27: =Offer_1!C78 -> 2026 | D27: =Offer_1!D78 -> 2027 | E27: =Offer_1!E78 -> 2028 | F27: =Offer_1!F78 -> 2029 | G27: =Offer_1!G78 -> 2030 | H27: =Offer_1!H78 -> 2031 | I27: =Offer_1!I78 -> 2032 | J27: =Offer_1!J78 -> 2033 | ... Q27: =Offer_1!Q78 -> 2040
A28: Total gross compensation
B29: =Offer_1!$B$4 -> Company A | C29: =Offer_1!C105 -> 250000 | D29: =Offer_1!D105 -> 472520 | E29: =Offer_1!E105 -> 427213.4 | F29: =Offer_1!F105 -> 448891.33 | G29: =Offer_1!G105 -> 470271.85 | H29: =Offer_1!H105 -> 468729.1 | I29: =Offer_1!I105 -> 482790.97 | J29: =Offer_1!J105 -> 497274.7 | ... Q29: =Offer_1!Q105 -> 554376.5
B30: =Offer_2!$B$4 -> Company B | C30: =Offer_2!C105 -> 247500 | D30: =Offer_2!D105 -> 390685 | E30: =Offer_2!E105 -> 399625.55 | F30: =Offer_2!F105 -> 449968.47 | G30: =Offer_2!G105 -> 504506.46 | H30: =Offer_2!H105 -> 440830.04 | I30: =Offer_2!I105 -> 454054.95 | J30: =Offer_2!J105 -> 467676.59 | ... Q30: =Offer_2!Q105 -> 529416.3
B31: =Offer_3!$B$4 -> Company C | C31: =Offer_3!C105 -> 215000 | D31: =Offer_3!D105 -> 357055 | E31: =Offer_3!E105 -> 367696.65 | F31: =Offer_3!F105 -> 406205.15 | G31: =Offer_3!G105 -> 447792.34 | H31: =Offer_3!H105 -> 492685.21 | I31: =Offer_3!I105 -> 391053.97 | J31: =Offer_3!J105 -> 402785.59 | ... Q31: =Offer_3!Q105 -> 464864.19
B32: =Current_Comp!$B$4 -> Current employer | C32: =Current_Comp!C105 -> 335500 | D32: =Current_Comp!D105 -> 345565 | E32: =Current_Comp!E105 -> 355931.95 | F32: =Current_Comp!F105 -> 366609.91 | G32: =Current_Comp!G105 -> 377608.21 | H32: =Current_Comp!H105 -> 388936.45 | I32: =Current_Comp!I105 -> 400604.55 | J32: =Current_Comp!J105 -> 412622.68 | ... Q32: =Current_Comp!Q105 -> 507473.85
A34: Cumulative gross compensation
B35: =Offer_1!$B$4 -> Company A | C35: =Offer_1!C106 -> 250000 | D35: =Offer_1!D106 -> 722520 | E35: =Offer_1!E106 -> 1149733.4 | F35: =Offer_1!F106 -> 1598624.7 | G35: =Offer_1!G106 -> 2068896.6 | H35: =Offer_1!H106 -> 2537625.7 | I35: =Offer_1!I106 -> 3020416.6 | J35: =Offer_1!J106 -> 3517691.3 | ... Q35: =Offer_1!Q106 -> 7385141.7
B36: =Offer_2!$B$4 -> Company B | C36: =Offer_2!C106 -> 247500 | D36: =Offer_2!D106 -> 638185 | E36: =Offer_2!E106 -> 1037810.6 | F36: =Offer_2!F106 -> 1487779 | G36: =Offer_2!G106 -> 1992285.5 | H36: =Offer_2!H106 -> 2433115.5 | I36: =Offer_2!I106 -> 2887170.5 | J36: =Offer_2!J106 -> 3354847.1 | ... Q36: =Offer_2!Q106 -> 7000141
B37: =Offer_3!$B$4 -> Company C | C37: =Offer_3!C106 -> 215000 | D37: =Offer_3!D106 -> 572055 | E37: =Offer_3!E106 -> 939751.65 | F37: =Offer_3!F106 -> 1345956.8 | G37: =Offer_3!G106 -> 1793749.1 | H37: =Offer_3!H106 -> 2286434.3 | I37: =Offer_3!I106 -> 2677488.3 | J37: =Offer_3!J106 -> 3080273.9 | ... Q37: =Offer_3!Q106 -> 6228681.9
B38: =Current_Comp!$B$4 -> Current employer | C38: =Current_Comp!C106 -> 335500 | D38: =Current_Comp!D106 -> 681065 | E38: =Current_Comp!E106 -> 1036996.9 | F38: =Current_Comp!F106 -> 1403606.9 | G38: =Current_Comp!G106 -> 1781215.1 | H38: =Current_Comp!H106 -> 2170151.5 | I38: =Current_Comp!I106 -> 2570756.1 | J38: =Current_Comp!J106 -> 2983378.7 | ... Q38: =Current_Comp!Q106 -> 6239935.6
A40: Highest cumulative to date | C40: =INDEX($B$35:$B$38,MATCH(MAX(C35:C38),C35:C38,0)) -> Current employer | D40: =INDEX($B$35:$B$38,MATCH(MAX(D35:D38),D35:D38,0)) -> Company A | E40: =INDEX($B$35:$B$38,MATCH(MAX(E35:E38),E35:E38,0)) -> Company A | F40: =INDEX($B$35:$B$38,MATCH(MAX(F35:F38),F35:F38,0)) -> Company A | G40: =INDEX($B$35:$B$38,MATCH(MAX(G35:G38),G35:G38,0)) -> Company A | H40: =INDEX($B$35:$B$38,MATCH(MAX(H35:H38),H35:H38,0)) -> Company A | I40: =INDEX($B$35:$B$38,MATCH(MAX(I35:I38),I35:I38,0)) -> Company A | J40: =INDEX($B$35:$B$38,MATCH(MAX(J35:J38),J35:J38,0)) -> Company A | ... Q40: =INDEX($B$35:$B$38,MATCH(MAX(Q35:Q38),Q35:Q38,0)) -> Company A
A42: CROSSOVER vs. baseline
A43: First year cumulative gross exceeds Current_Comp
A44: Helper (year index if ahead, else 9999)
B45: =Offer_1!$B$4 -> Company A | C45: =IF(Offer_1!C106>Current_Comp!C106,C$27-Offer_1!$B$6+1,9999) -> 9999 | D45: =IF(Offer_1!D106>Current_Comp!D106,D$27-Offer_1!$B$6+1,9999) -> 2 | E45: =IF(Offer_1!E106>Current_Comp!E106,E$27-Offer_1!$B$6+1,9999) -> 3 | F45: =IF(Offer_1!F106>Current_Comp!F106,F$27-Offer_1!$B$6+1,9999) -> 4 | G45: =IF(Offer_1!G106>Current_Comp!G106,G$27-Offer_1!$B$6+1,9999) -> 5 | H45: =IF(Offer_1!H106>Current_Comp!H106,H$27-Offer_1!$B$6+1,9999) -> 6 | I45: =IF(Offer_1!I106>Current_Comp!I106,I$27-Offer_1!$B$6+1,9999) -> 7 | J45: =IF(Offer_1!J106>Current_Comp!J106,J$27-Offer_1!$B$6+1,9999) -> 8 | ... Q45: =IF(Offer_1!Q106>Current_Comp!Q106,Q$27-Offer_1!$B$6+1,9999) -> 15
B46: =Offer_2!$B$4 -> Company B | C46: =IF(Offer_2!C106>Current_Comp!C106,C$27-Offer_2!$B$6+1,9999) -> 9999 | D46: =IF(Offer_2!D106>Current_Comp!D106,D$27-Offer_2!$B$6+1,9999) -> 9999 | E46: =IF(Offer_2!E106>Current_Comp!E106,E$27-Offer_2!$B$6+1,9999) -> 3 | F46: =IF(Offer_2!F106>Current_Comp!F106,F$27-Offer_2!$B$6+1,9999) -> 4 | G46: =IF(Offer_2!G106>Current_Comp!G106,G$27-Offer_2!$B$6+1,9999) -> 5 | H46: =IF(Offer_2!H106>Current_Comp!H106,H$27-Offer_2!$B$6+1,9999) -> 6 | I46: =IF(Offer_2!I106>Current_Comp!I106,I$27-Offer_2!$B$6+1,9999) -> 7 | J46: =IF(Offer_2!J106>Current_Comp!J106,J$27-Offer_2!$B$6+1,9999) -> 8 | ... Q46: =IF(Offer_2!Q106>Current_Comp!Q106,Q$27-Offer_2!$B$6+1,9999) -> 15
B47: =Offer_3!$B$4 -> Company C | C47: =IF(Offer_3!C106>Current_Comp!C106,C$27-Offer_3!$B$6+1,9999) -> 9999 | D47: =IF(Offer_3!D106>Current_Comp!D106,D$27-Offer_3!$B$6+1,9999) -> 9999 | E47: =IF(Offer_3!E106>Current_Comp!E106,E$27-Offer_3!$B$6+1,9999) -> 9999 | F47: =IF(Offer_3!F106>Current_Comp!F106,F$27-Offer_3!$B$6+1,9999) -> 9999 | G47: =IF(Offer_3!G106>Current_Comp!G106,G$27-Offer_3!$B$6+1,9999) -> 5 | H47: =IF(Offer_3!H106>Current_Comp!H106,H$27-Offer_3!$B$6+1,9999) -> 6 | I47: =IF(Offer_3!I106>Current_Comp!I106,I$27-Offer_3!$B$6+1,9999) -> 7 | J47: =IF(Offer_3!J106>Current_Comp!J106,J$27-Offer_3!$B$6+1,9999) -> 8 | ... Q47: =IF(Offer_3!Q106>Current_Comp!Q106,Q$27-Offer_3!$B$6+1,9999) -> 9999
A49: Crossover year (tenure year)
B50: =Offer_1!$B$4 -> Company A | C50: =IF(MIN(C45:Q45)=9999,"Never within horizon",MIN(C45:Q45)) -> 2
B51: =Offer_2!$B$4 -> Company B | C51: =IF(MIN(C46:Q46)=9999,"Never within horizon",MIN(C46:Q46)) -> 3
...

Sheet Validation
A1: ENGINE VALIDATION vs. THE ORIGINAL WORKBOOK
A2: Reproduces row 8 of the original "CompOffer Comparison" tab, which was the one refresher row that was free of divisor bugs.
A3: If the CHECK row reads TIE across the board, this tranche engine matches the original where the original was correct.
A5: Reference case inputs
A6: First refresher grant value ($) | B6: 150000
A7: Refresher grant growth %/yr | B7: 0.03
A8: Share price (flat — 0% appreciation) | B8: 150
A9: First refresher grant year | B9: 2021
A10: Vesting: 25% in each of years 1-4 after grant
A12: Year index | C12: 1 | D12: 2 | E12: 3 | F12: 4 | G12: 5 | H12: 6 | I12: 7 | J12: 8 | K12: 9 | L12: 10
A13: Calendar year | C13: =$B$9 -> 2021 | D13: =C13+1 -> 2022 | E13: =D13+1 -> 2023 | F13: =E13+1 -> 2024 | G13: =F13+1 -> 2025 | H13: =G13+1 -> 2026 | I13: =H13+1 -> 2027 | J13: =I13+1 -> 2028 | K13: =J13+1 -> 2029 | L13: =K13+1 -> 2030
A15: Grant ledger | S15: Grant year | T15: Grant value ($) | U15: Shares
A16: Refresher grant 1 | C16: =IF(AND(C$13-$S16>=1,C$13-$S16<=4),0.25,0)*$U16*$B$8 -> 0 | D16: =IF(AND(D$13-$S16>=1,D$13-$S16<=4),0.25,0)*$U16*$B$8 -> 37500 | E16: =IF(AND(E$13-$S16>=1,E$13-$S16<=4),0.25,0)*$U16*$B$8 -> 37500 | F16: =IF(AND(F$13-$S16>=1,F$13-$S16<=4),0.25,0)*$U16*$B$8 -> 37500 | G16: =IF(AND(G$13-$S16>=1,G$13-$S16<=4),0.25,0)*$U16*$B$8 -> 37500 | H16: =IF(AND(H$13-$S16>=1,H$13-$S16<=4),0.25,0)*$U16*$B$8 -> 0 | I16: =IF(AND(I$13-$S16>=1,I$13-$S16<=4),0.25,0)*$U16*$B$8 -> 0 | J16: =IF(AND(J$13-$S16>=1,J$13-$S16<=4),0.25,0)*$U16*$B$8 -> 0 | ... L16: =IF(AND(L$13-$S16>=1,L$13-$S16<=4),0.25,0)*$U16*$B$8 -> 0 | S16: =$B$9+0 -> 2021 | T16: =$B$6*(1+$B$7)^0 -> 150000 | U16: =$T16/$B$8 -> 1000
A17: Refresher grant 2 | C17: =IF(AND(C$13-$S17>=1,C$13-$S17<=4),0.25,0)*$U17*$B$8 -> 0 | D17: =IF(AND(D$13-$S17>=1,D$13-$S17<=4),0.25,0)*$U17*$B$8 -> 0 | E17: =IF(AND(E$13-$S17>=1,E$13-$S17<=4),0.25,0)*$U17*$B$8 -> 38625 | F17: =IF(AND(F$13-$S17>=1,F$13-$S17<=4),0.25,0)*$U17*$B$8 -> 38625 | G17: =IF(AND(G$13-$S17>=1,G$13-$S17<=4),0.25,0)*$U17*$B$8 -> 38625 | H17: =IF(AND(H$13-$S17>=1,H$13-$S17<=4),0.25,0)*$U17*$B$8 -> 38625 | I17: =IF(AND(I$13-$S17>=1,I$13-$S17<=4),0.25,0)*$U17*$B$8 -> 0 | J17: =IF(AND(J$13-$S17>=1,J$13-$S17<=4),0.25,0)*$U17*$B$8 -> 0 | ... L17: =IF(AND(L$13-$S17>=1,L$13-$S17<=4),0.25,0)*$U17*$B$8 -> 0 | S17: =$B$9+1 -> 2022 | T17: =$B$6*(1+$B$7)^1 -> 154500 | U17: =$T17/$B$8 -> 1030
A18: Refresher grant 3 | C18: =IF(AND(C$13-$S18>=1,C$13-$S18<=4),0.25,0)*$U18*$B$8 -> 0 | D18: =IF(AND(D$13-$S18>=1,D$13-$S18<=4),0.25,0)*$U18*$B$8 -> 0 | E18: =IF(AND(E$13-$S18>=1,E$13-$S18<=4),0.25,0)*$U18*$B$8 -> 0 | F18: =IF(AND(F$13-$S18>=1,F$13-$S18<=4),0.25,0)*$U18*$B$8 -> 39783.75 | G18: =IF(AND(G$13-$S18>=1,G$13-$S18<=4),0.25,0)*$U18*$B$8 -> 39783.75 | H18: =IF(AND(H$13-$S18>=1,H$13-$S18<=4),0.25,0)*$U18*$B$8 -> 39783.75 | I18: =IF(AND(I$13-$S18>=1,I$13-$S18<=4),0.25,0)*$U18*$B$8 -> 39783.75 | J18: =IF(AND(J$13-$S18>=1,J$13-$S18<=4),0.25,0)*$U18*$B$8 -> 0 | ... L18: =IF(AND(L$13-$S18>=1,L$13-$S18<=4),0.25,0)*$U18*$B$8 -> 0 | S18: =$B$9+2 -> 2023 | T18: =$B$6*(1+$B$7)^2 -> 159135 | U18: =$T18/$B$8 -> 1060.9
A19: Refresher grant 4 | C19: =IF(AND(C$13-$S19>=1,C$13-$S19<=4),0.25,0)*$U19*$B$8 -> 0 | D19: =IF(AND(D$13-$S19>=1,D$13-$S19<=4),0.25,0)*$U19*$B$8 -> 0 | E19: =IF(AND(E$13-$S19>=1,E$13-$S19<=4),0.25,0)*$U19*$B$8 -> 0 | F19: =IF(AND(F$13-$S19>=1,F$13-$S19<=4),0.25,0)*$U19*$B$8 -> 0 | G19: =IF(AND(G$13-$S19>=1,G$13-$S19<=4),0.25,0)*$U19*$B$8 -> 40977.262 | H19: =IF(AND(H$13-$S19>=1,H$13-$S19<=4),0.25,0)*$U19*$B$8 -> 40977.262 | I19: =IF(AND(I$13-$S19>=1,I$13-$S19<=4),0.25,0)*$U19*$B$8 -> 40977.262 | J19: =IF(AND(J$13-$S19>=1,J$13-$S19<=4),0.25,0)*$U19*$B$8 -> 40977.262 | ... L19: =IF(AND(L$13-$S19>=1,L$13-$S19<=4),0.25,0)*$U19*$B$8 -> 0 | S19: =$B$9+3 -> 2024 | T19: =$B$6*(1+$B$7)^3 -> 163909.05 | U19: =$T19/$B$8 -> 1092.727
A20: Refresher grant 5 | C20: =IF(AND(C$13-$S20>=1,C$13-$S20<=4),0.25,0)*$U20*$B$8 -> 0 | D20: =IF(AND(D$13-$S20>=1,D$13-$S20<=4),0.25,0)*$U20*$B$8 -> 0 | E20: =IF(AND(E$13-$S20>=1,E$13-$S20<=4),0.25,0)*$U20*$B$8 -> 0 | F20: =IF(AND(F$13-$S20>=1,F$13-$S20<=4),0.25,0)*$U20*$B$8 -> 0 | G20: =IF(AND(G$13-$S20>=1,G$13-$S20<=4),0.25,0)*$U20*$B$8 -> 0 | H20: =IF(AND(H$13-$S20>=1,H$13-$S20<=4),0.25,0)*$U20*$B$8 -> 42206.58 | I20: =IF(AND(I$13-$S20>=1,I$13-$S20<=4),0.25,0)*$U20*$B$8 -> 42206.58 | J20: =IF(AND(J$13-$S20>=1,J$13-$S20<=4),0.25,0)*$U20*$B$8 -> 42206.58 | ... L20: =IF(AND(L$13-$S20>=1,L$13-$S20<=4),0.25,0)*$U20*$B$8 -> 0 | S20: =$B$9+4 -> 2025 | T20: =$B$6*(1+$B$7)^4 -> 168826.32 | U20: =$T20/$B$8 -> 1125.5088
A21: Refresher grant 6 | C21: =IF(AND(C$13-$S21>=1,C$13-$S21<=4),0.25,0)*$U21*$B$8 -> 0 | D21: =IF(AND(D$13-$S21>=1,D$13-$S21<=4),0.25,0)*$U21*$B$8 -> 0 | E21: =IF(AND(E$13-$S21>=1,E$13-$S21<=4),0.25,0)*$U21*$B$8 -> 0 | F21: =IF(AND(F$13-$S21>=1,F$13-$S21<=4),0.25,0)*$U21*$B$8 -> 0 | G21: =IF(AND(G$13-$S21>=1,G$13-$S21<=4),0.25,0)*$U21*$B$8 -> 0 | H21: =IF(AND(H$13-$S21>=1,H$13-$S21<=4),0.25,0)*$U21*$B$8 -> 0 | I21: =IF(AND(I$13-$S21>=1,I$13-$S21<=4),0.25,0)*$U21*$B$8 -> 43472.778 | J21: =IF(AND(J$13-$S21>=1,J$13-$S21<=4),0.25,0)*$U21*$B$8 -> 43472.778 | ... L21: =IF(AND(L$13-$S21>=1,L$13-$S21<=4),0.25,0)*$U21*$B$8 -> 43472.778 | S21: =$B$9+5 -> 2026 | T21: =$B$6*(1+$B$7)^5 -> 173891.11 | U21: =$T21/$B$8 -> 1159.2741
A22: Refresher grant 7 | C22: =IF(AND(C$13-$S22>=1,C$13-$S22<=4),0.25,0)*$U22*$B$8 -> 0 | D22: =IF(AND(D$13-$S22>=1,D$13-$S22<=4),0.25,0)*$U22*$B$8 -> 0 | E22: =IF(AND(E$13-$S22>=1,E$13-$S22<=4),0.25,0)*$U22*$B$8 -> 0 | F22: =IF(AND(F$13-$S22>=1,F$13-$S22<=4),0.25,0)*$U22*$B$8 -> 0 | G22: =IF(AND(G$13-$S22>=1,G$13-$S22<=4),0.25,0)*$U22*$B$8 -> 0 | H22: =IF(AND(H$13-$S22>=1,H$13-$S22<=4),0.25,0)*$U22*$B$8 -> 0 | I22: =IF(AND(I$13-$S22>=1,I$13-$S22<=4),0.25,0)*$U22*$B$8 -> 0 | J22: =IF(AND(J$13-$S22>=1,J$13-$S22<=4),0.25,0)*$U22*$B$8 -> 44776.961 | ... L22: =IF(AND(L$13-$S22>=1,L$13-$S22<=4),0.25,0)*$U22*$B$8 -> 44776.961 | S22: =$B$9+6 -> 2027 | T22: =$B$6*(1+$B$7)^6 -> 179107.84 | U22: =$T22/$B$8 -> 1194.0523
A23: Refresher grant 8 | C23: =IF(AND(C$13-$S23>=1,C$13-$S23<=4),0.25,0)*$U23*$B$8 -> 0 | D23: =IF(AND(D$13-$S23>=1,D$13-$S23<=4),0.25,0)*$U23*$B$8 -> 0 | E23: =IF(AND(E$13-$S23>=1,E$13-$S23<=4),0.25,0)*$U23*$B$8 -> 0 | F23: =IF(AND(F$13-$S23>=1,F$13-$S23<=4),0.25,0)*$U23*$B$8 -> 0 | G23: =IF(AND(G$13-$S23>=1,G$13-$S23<=4),0.25,0)*$U23*$B$8 -> 0 | H23: =IF(AND(H$13-$S23>=1,H$13-$S23<=4),0.25,0)*$U23*$B$8 -> 0 | I23: =IF(AND(I$13-$S23>=1,I$13-$S23<=4),0.25,0)*$U23*$B$8 -> 0 | J23: =IF(AND(J$13-$S23>=1,J$13-$S23<=4),0.25,0)*$U23*$B$8 -> 0 | ... L23: =IF(AND(L$13-$S23>=1,L$13-$S23<=4),0.25,0)*$U23*$B$8 -> 46120.27 | S23: =$B$9+7 -> 2028 | T23: =$B$6*(1+$B$7)^7 -> 184481.08 | U23: =$T23/$B$8 -> 1229.8739
A24: Refresher grant 9 | C24: =IF(AND(C$13-$S24>=1,C$13-$S24<=4),0.25,0)*$U24*$B$8 -> 0 | D24: =IF(AND(D$13-$S24>=1,D$13-$S24<=4),0.25,0)*$U24*$B$8 -> 0 | E24: =IF(AND(E$13-$S24>=1,E$13-$S24<=4),0.25,0)*$U24*$B$8 -> 0 | F24: =IF(AND(F$13-$S24>=1,F$13-$S24<=4),0.25,0)*$U24*$B$8 -> 0 | G24: =IF(AND(G$13-$S24>=1,G$13-$S24<=4),0.25,0)*$U24*$B$8 -> 0 | H24: =IF(AND(H$13-$S24>=1,H$13-$S24<=4),0.25,0)*$U24*$B$8 -> 0 | I24: =IF(AND(I$13-$S24>=1,I$13-$S24<=4),0.25,0)*$U24*$B$8 -> 0 | J24: =IF(AND(J$13-$S24>=1,J$13-$S24<=4),0.25,0)*$U24*$B$8 -> 0 | ... L24: =IF(AND(L$13-$S24>=1,L$13-$S24<=4),0.25,0)*$U24*$B$8 -> 47503.878 | S24: =$B$9+8 -> 2029 | T24: =$B$6*(1+$B$7)^8 -> 190015.51 | U24: =$T24/$B$8 -> 1266.7701
A25: Refresher grant 10 | C25: =IF(AND(C$13-$S25>=1,C$13-$S25<=4),0.25,0)*$U25*$B$8 -> 0 | D25: =IF(AND(D$13-$S25>=1,D$13-$S25<=4),0.25,0)*$U25*$B$8 -> 0 | E25: =IF(AND(E$13-$S25>=1,E$13-$S25<=4),0.25,0)*$U25*$B$8 -> 0 | F25: =IF(AND(F$13-$S25>=1,F$13-$S25<=4),0.25,0)*$U25*$B$8 -> 0 | G25: =IF(AND(G$13-$S25>=1,G$13-$S25<=4),0.25,0)*$U25*$B$8 -> 0 | H25: =IF(AND(H$13-$S25>=1,H$13-$S25<=4),0.25,0)*$U25*$B$8 -> 0 | I25: =IF(AND(I$13-$S25>=1,I$13-$S25<=4),0.25,0)*$U25*$B$8 -> 0 | J25: =IF(AND(J$13-$S25>=1,J$13-$S25<=4),0.25,0)*$U25*$B$8 -> 0 | ... L25: =IF(AND(L$13-$S25>=1,L$13-$S25<=4),0.25,0)*$U25*$B$8 -> 0 | S25: =$B$9+9 -> 2030 | T25: =$B$6*(1+$B$7)^9 -> 195715.98 | U25: =$T25/$B$8 -> 1304.7732
A27: Refresher vest — THIS ENGINE | C27: =SUM(C16:C25) -> 0 | D27: =SUM(D16:D25) -> 37500 | E27: =SUM(E16:E25) -> 76125 | F27: =SUM(F16:F25) -> 115908.75 | G27: =SUM(G16:G25) -> 156886.01 | H27: =SUM(H16:H25) -> 161592.59 | I27: =SUM(I16:I25) -> 166440.37 | J27: =SUM(J16:J25) -> 171433.58 | ... L27: =SUM(L16:L25) -> 181873.89
A28: Refresher vest — ORIGINAL WORKBOOK row 8 | C28: 0 | D28: 37500 | E28: 76125 | F28: 115908.75 | G28: 156886.01 | H28: 161592.59 | I28: 166440.37 | J28: 171433.58 | K28: 176576.59 | L28: 181873.89
A29: Difference | C29: =C27-C28 -> 0 | D29: =D27-D28 -> 0 | E29: =E27-E28 -> 0 | F29: =F27-F28 -> 0 | G29: =G27-G28 -> 0.0025 | H29: =H27-H28 -> 0.002875 | I29: =I27-I28 -> 0.00066125 | J29: =J27-J28 -> 0.0017810875 | ... L29: =L27-L28 -> -0.0030884442
A30: CHECK | C30: =IF(ABS(C29)<0.02,"TIE","MISMATCH") -> TIE | D30: =IF(ABS(D29)<0.02,"TIE","MISMATCH") -> TIE | E30: =IF(ABS(E29)<0.02,"TIE","MISMATCH") -> TIE | F30: =IF(ABS(F29)<0.02,"TIE","MISMATCH") -> TIE | G30: =IF(ABS(G29)<0.02,"TIE","MISMATCH") -> TIE | H30: =IF(ABS(H29)<0.02,"TIE","MISMATCH") -> TIE | I30: =IF(ABS(I29)<0.02,"TIE","MISMATCH") -> TIE | J30: =IF(ABS(J29)<0.02,"TIE","MISMATCH") -> TIE | ... L30: =IF(ABS(L29)<0.02,"TIE","MISMATCH") -> TIE
A32: Original values are cells D8:L8 of "CompOffer Comparison" in 10_year_Comp_Comparison_Calc.xlsx, rounded to the cent.
A33: The original vests 25% in the grant year itself. This tab sets the first grant to 2021 so its year-1 vest lands in 2022 and the two series align.
A34: That timing convention is an input on each offer tab (row 22), because a real new-hire grant normally has its first vest a year after the grant date.
